[2025-03-19T18:51:54.645+0000] {local_task_job_runner.py:123} INFO - ::group::Pre task execution logs
[2025-03-19T18:51:54.651+0000] {taskinstance.py:2614} INFO - Dependencies all met for dep_context=non-requeueable deps ti=<TaskInstance: dbt_run_dag.dbt_run manual__2025-03-19T18:51:52.218096+00:00 [queued]>
[2025-03-19T18:51:54.720+0000] {taskinstance.py:2614} INFO - Dependencies all met for dep_context=requeueable deps ti=<TaskInstance: dbt_run_dag.dbt_run manual__2025-03-19T18:51:52.218096+00:00 [queued]>
[2025-03-19T18:51:54.720+0000] {taskinstance.py:2867} INFO - Starting attempt 1 of 1
[2025-03-19T18:51:54.724+0000] {taskinstance.py:2890} INFO - Executing <Task(BashOperator): dbt_run> on 2025-03-19 18:51:52.218096+00:00
[2025-03-19T18:51:54.727+0000] {warnings.py:112} WARNING - /home/***/.local/lib/python3.12/site-packages/***/task/task_runner/standard_task_runner.py:70: DeprecationWarning: This process (pid=67) is multi-threaded, use of fork() may lead to deadlocks in the child.
  pid = os.fork()

[2025-03-19T18:51:54.727+0000] {standard_task_runner.py:72} INFO - Started process 68 to run task
[2025-03-19T18:51:54.728+0000] {standard_task_runner.py:104} INFO - Running: ['***', 'tasks', 'run', 'dbt_run_dag', 'dbt_run', 'manual__2025-03-19T18:51:52.218096+00:00', '--job-id', '36', '--raw', '--subdir', 'DAGS_FOLDER/dbt_***_dag.py', '--cfg-path', '/tmp/tmp8k48r4s5']
[2025-03-19T18:51:54.728+0000] {standard_task_runner.py:105} INFO - Job 36: Subtask dbt_run
[2025-03-19T18:51:54.744+0000] {task_command.py:467} INFO - Running <TaskInstance: dbt_run_dag.dbt_run manual__2025-03-19T18:51:52.218096+00:00 [running]> on host 8a35bbdad323
[2025-03-19T18:51:54.768+0000] {taskinstance.py:3134} INFO - Exporting env vars: AIRFLOW_CTX_DAG_OWNER='***' AIRFLOW_CTX_DAG_ID='dbt_run_dag' AIRFLOW_CTX_TASK_ID='dbt_run' AIRFLOW_CTX_EXECUTION_DATE='2025-03-19T18:51:52.218096+00:00' AIRFLOW_CTX_TRY_NUMBER='1' AIRFLOW_CTX_DAG_RUN_ID='manual__2025-03-19T18:51:52.218096+00:00'
[2025-03-19T18:51:54.769+0000] {logging_mixin.py:190} INFO - Task instance is in running state
[2025-03-19T18:51:54.769+0000] {logging_mixin.py:190} INFO -  Previous state of the Task instance: queued
[2025-03-19T18:51:54.769+0000] {logging_mixin.py:190} INFO - Current task name:dbt_run state:running start_date:2025-03-19 18:51:54.651511+00:00
[2025-03-19T18:51:54.769+0000] {logging_mixin.py:190} INFO - Dag name:dbt_run_dag and current dag run status:running
[2025-03-19T18:51:54.770+0000] {taskinstance.py:732} INFO - ::endgroup::
[2025-03-19T18:51:54.770+0000] {subprocess.py:78} INFO - Tmp dir root location: /tmp
[2025-03-19T18:51:54.770+0000] {subprocess.py:88} INFO - Running command: ['/usr/bin/bash', '-c', '/home/***/.local/bin/dbt run']
[2025-03-19T18:51:54.774+0000] {subprocess.py:99} INFO - Output:
[2025-03-19T18:51:54.774+0000] {subprocess.py:106} INFO - /usr/bin/bash: line 1: /home/***/.local/bin/dbt: No such file or directory
[2025-03-19T18:51:54.774+0000] {subprocess.py:110} INFO - Command exited with return code 127
[2025-03-19T18:51:54.778+0000] {taskinstance.py:3313} ERROR - Task failed with exception
Traceback (most recent call last):
  File "/home/airflow/.local/lib/python3.12/site-packages/airflow/models/taskinstance.py", line 768, in _execute_task
    result = _execute_callable(context=context, **execute_callable_kwargs)
             ^^^^^^^^^^^^^^^^^^^^^^^^^^^^^^^^^^^^^^^^^^^^^^^^^^^^^^^^^^^^^
  File "/home/airflow/.local/lib/python3.12/site-packages/airflow/models/taskinstance.py", line 734, in _execute_callable
    return ExecutionCallableRunner(
           ^^^^^^^^^^^^^^^^^^^^^^^^
  File "/home/airflow/.local/lib/python3.12/site-packages/airflow/utils/operator_helpers.py", line 252, in run
    return self.func(*args, **kwargs)
           ^^^^^^^^^^^^^^^^^^^^^^^^^^
  File "/home/airflow/.local/lib/python3.12/site-packages/airflow/models/baseoperator.py", line 424, in wrapper
    return func(self, *args, **kwargs)
           ^^^^^^^^^^^^^^^^^^^^^^^^^^^
  File "/home/airflow/.local/lib/python3.12/site-packages/airflow/operators/bash.py", line 276, in execute
    raise AirflowException(
airflow.exceptions.AirflowException: Bash command failed. The command returned a non-zero exit code 127.
[2025-03-19T18:51:54.780+0000] {logging_mixin.py:190} INFO - Task instance in failure state
[2025-03-19T18:51:54.780+0000] {logging_mixin.py:190} INFO - Task start:2025-03-19 18:51:54.651511+00:00 end:2025-03-19 18:51:54.780664+00:00 duration:0.129153
[2025-03-19T18:51:54.781+0000] {logging_mixin.py:190} INFO - Task:<Task(BashOperator): dbt_run> dag:<DAG: dbt_run_dag> dagrun:<DagRun dbt_run_dag @ 2025-03-19 18:51:52.218096+00:00: manual__2025-03-19T18:51:52.218096+00:00, state:running, queued_at: 2025-03-19 18:51:52.232308+00:00. externally triggered: True>
[2025-03-19T18:51:54.781+0000] {logging_mixin.py:190} INFO - Failure caused by Bash command failed. The command returned a non-zero exit code 127.
[2025-03-19T18:51:54.781+0000] {taskinstance.py:1226} INFO - Marking task as FAILED. dag_id=dbt_run_dag, task_id=dbt_run, run_id=manual__2025-03-19T18:51:52.218096+00:00, execution_date=20250319T185152, start_date=20250319T185154, end_date=20250319T185154
[2025-03-19T18:51:54.788+0000] {taskinstance.py:341} INFO - ::group::Post task execution logs
[2025-03-19T18:51:54.788+0000] {standard_task_runner.py:124} ERROR - Failed to execute job 36 for task dbt_run (Bash command failed. The command returned a non-zero exit code 127.; 68)
Traceback (most recent call last):
  File "/home/airflow/.local/lib/python3.12/site-packages/airflow/task/task_runner/standard_task_runner.py", line 117, in _start_by_fork
    ret = args.func(args, dag=self.dag)
          ^^^^^^^^^^^^^^^^^^^^^^^^^^^^^
  File "/home/airflow/.local/lib/python3.12/site-packages/airflow/cli/cli_config.py", line 49, in command
    return func(*args, **kwargs)
           ^^^^^^^^^^^^^^^^^^^^^
  File "/home/airflow/.local/lib/python3.12/site-packages/airflow/utils/cli.py", line 116, in wrapper
    return f(*args, **kwargs)
           ^^^^^^^^^^^^^^^^^^
  File "/home/airflow/.local/lib/python3.12/site-packages/airflow/cli/commands/task_command.py", line 483, in task_run
    task_return_code = _run_task_by_selected_method(args, _dag, ti)
                       ^^^^^^^^^^^^^^^^^^^^^^^^^^^^^^^^^^^^^^^^^^^^
  File "/home/airflow/.local/lib/python3.12/site-packages/airflow/cli/commands/task_command.py", line 256, in _run_task_by_selected_method
    return _run_raw_task(args, ti)
           ^^^^^^^^^^^^^^^^^^^^^^^
  File "/home/airflow/.local/lib/python3.12/site-packages/airflow/cli/commands/task_command.py", line 341, in _run_raw_task
    return ti._run_raw_task(
           ^^^^^^^^^^^^^^^^^
  File "/home/airflow/.local/lib/python3.12/site-packages/airflow/utils/session.py", line 97, in wrapper
    return func(*args, session=session, **kwargs)
           ^^^^^^^^^^^^^^^^^^^^^^^^^^^^^^^^^^^^^^
  File "/home/airflow/.local/lib/python3.12/site-packages/airflow/models/taskinstance.py", line 3006, in _run_raw_task
    return _run_raw_task(
           ^^^^^^^^^^^^^^
  File "/home/airflow/.local/lib/python3.12/site-packages/airflow/models/taskinstance.py", line 274, in _run_raw_task
    TaskInstance._execute_task_with_callbacks(
  File "/home/airflow/.local/lib/python3.12/site-packages/airflow/models/taskinstance.py", line 3161, in _execute_task_with_callbacks
    result = self._execute_task(context, task_orig)
             ^^^^^^^^^^^^^^^^^^^^^^^^^^^^^^^^^^^^^^
  File "/home/airflow/.local/lib/python3.12/site-packages/airflow/models/taskinstance.py", line 3185, in _execute_task
    return _execute_task(self, context, task_orig)
           ^^^^^^^^^^^^^^^^^^^^^^^^^^^^^^^^^^^^^^^
  File "/home/airflow/.local/lib/python3.12/site-packages/airflow/models/taskinstance.py", line 768, in _execute_task
    result = _execute_callable(context=context, **execute_callable_kwargs)
             ^^^^^^^^^^^^^^^^^^^^^^^^^^^^^^^^^^^^^^^^^^^^^^^^^^^^^^^^^^^^^
  File "/home/airflow/.local/lib/python3.12/site-packages/airflow/models/taskinstance.py", line 734, in _execute_callable
    return ExecutionCallableRunner(
           ^^^^^^^^^^^^^^^^^^^^^^^^
  File "/home/airflow/.local/lib/python3.12/site-packages/airflow/utils/operator_helpers.py", line 252, in run
    return self.func(*args, **kwargs)
           ^^^^^^^^^^^^^^^^^^^^^^^^^^
  File "/home/airflow/.local/lib/python3.12/site-packages/airflow/models/baseoperator.py", line 424, in wrapper
    return func(self, *args, **kwargs)
           ^^^^^^^^^^^^^^^^^^^^^^^^^^^
  File "/home/airflow/.local/lib/python3.12/site-packages/airflow/operators/bash.py", line 276, in execute
    raise AirflowException(
airflow.exceptions.AirflowException: Bash command failed. The command returned a non-zero exit code 127.
[2025-03-19T18:51:54.829+0000] {local_task_job_runner.py:266} INFO - Task exited with return code 1
[2025-03-19T18:51:54.835+0000] {taskinstance.py:3901} INFO - 0 downstream tasks scheduled from follow-on schedule check
[2025-03-19T18:51:54.835+0000] {local_task_job_runner.py:245} INFO - ::endgroup::
